Workbook

Sheet Planilha de Pedidos SONIC
B1: PLANILHA DE PEDIDOS SONIC
H2: NÃO EDITAR CÉLULAS EM AMARELHO
B3: ID: | C3: 903075 | E3: N° de Pedido: | F3: OC 647.13.26
B4: Cliente: | C4: IMOUVIR | E4: CNPJ: | F4: 35.342.560/0001-09
B5: *Razão Social: | C5: INSTITUTO MAÇÔNICO OUVIR - IMOUVIR
B6: Endereço de Entrega | C6: ASSOCIAÇÃO DOS SURDOS E MUDOS DE UBERLÂNDIA - ASUL A/C FGA BRENDDA MAIA DE SOUSA RUA MATHEUS VAZ N° 865 , BAIRRO: LUIZOTE DE FREITAS II UBERLÂNDIA / MG CEP 38.414-308 | E6: CEP | F6: 38.414-308
B7: Nome do Paciente | C7: 647.13.26 - PCT ROMILDA ALVES FARIA - UBERLÂNDIA - 28.04.26 | E7: Cidade | F7: UBERLÂNDIA - MT
B8: Condição de Pagamento | C8: BOLETO 30 DIAS | E8: PGTO | F8: BOLETO 30 DIAS
B9: Código Pagamento | C9: =VLOOKUP(C8,Sheet1!G:H,2,FALSE) -> 009
B10: NF: | C10: TX Vl. Paulista
B11: PEDIDO
B12: Código | C12: Descrição | D12: Quantidade | E12: Valor unitário | F12: Valor total
B13: =IFERROR(VLOOKUP(C13,Sheet1!B:C,2,FALSE), ) -> 240470 | C13: RADIANT 20 MNR RECARREGÁVEL | D13: 2 | E13: 1100 | F13: =E13*D13 -> 2200
B14: =IFERROR(VLOOKUP(C14,Sheet1!B:C,2,FALSE), ) -> 225683 | C14: CARREGADOR SONIC PLUS | D14: 1 | E14: 700 | F14: =E14*D14 -> 700
B15: =IFERROR(VLOOKUP(C15,Sheet1!B:C,2,FALSE), ) -> 0 | E15: =IFERROR(VLOOKUP(C15,Sheet1!B:D,3,FALSE),0) -> 0 | F15: =E15*D15 -> 0
B16: =IFERROR(VLOOKUP(C16,Sheet1!B:C,2,FALSE), ) -> 0 | E16: =IFERROR(VLOOKUP(C16,Sheet1!B:D,3,FALSE),0) -> 0 | F16: =E16*D16 -> 0
B17: =IFERROR(VLOOKUP(C17,Sheet1!B:C,2,FALSE), ) -> 0 | E17: =IFERROR(VLOOKUP(C17,Sheet1!B:D,3,FALSE),0) -> 0 | F17: =E17*D17 -> 0
B18: =IFERROR(VLOOKUP(C18,Sheet1!B:C,2,FALSE), ) -> 0 | E18: =IFERROR(VLOOKUP(C18,Sheet1!B:D,3,FALSE),0) -> 0 | F18: =E18*D18 -> 0
B19: =IFERROR(VLOOKUP(C19,Sheet1!B:C,2,FALSE), ) -> 0 | E19: =IFERROR(VLOOKUP(C19,Sheet1!B:D,3,FALSE),0) -> 0 | F19: =E19*D19 -> 0
B20: =IFERROR(VLOOKUP(C20,Sheet1!B:C,2,FALSE), ) -> 0 | E20: =IFERROR(VLOOKUP(C20,Sheet1!B:D,3,FALSE),0) -> 0 | F20: =E20*D20 -> 0
B21: =IFERROR(VLOOKUP(C21,Sheet1!B:C,2,FALSE), ) -> 0 | E21: =IFERROR(VLOOKUP(C21,Sheet1!B:D,3,FALSE),0) -> 0 | F21: =E21*D21 -> 0
B22: =IFERROR(VLOOKUP(C22,Sheet1!B:C,2,FALSE), ) -> 0 | E22: =IFERROR(VLOOKUP(C22,Sheet1!B:D,3,FALSE),0) -> 0 | F22: =E22*D22 -> 0
B23: =IFERROR(VLOOKUP(C23,Sheet1!B:C,2,FALSE), ) -> 0 | E23: =IFERROR(VLOOKUP(C23,Sheet1!B:D,3,FALSE),0) -> 0 | F23: =E23*D23 -> 0
B24: =IFERROR(VLOOKUP(C24,Sheet1!B:C,2,FALSE), ) -> 0 | E24: =IFERROR(VLOOKUP(C24,Sheet1!B:D,3,FALSE),0) -> 0 | F24: =E24*D24 -> 0
B25: =IFERROR(VLOOKUP(C25,Sheet1!B:C,2,FALSE), ) -> 0 | E25: =IFERROR(VLOOKUP(C25,Sheet1!B:D,3,FALSE),0) -> 0 | F25: =E25*D25 -> 0
B26: =IFERROR(VLOOKUP(C26,Sheet1!B:C,2,FALSE), ) -> 0 | E26: =IFERROR(VLOOKUP(C26,Sheet1!B:D,3,FALSE),0) -> 0 | F26: =E26*D26 -> 0
B27: =IFERROR(VLOOKUP(C27,Sheet1!B:C,2,FALSE), ) -> 0 | E27: =IFERROR(VLOOKUP(C27,Sheet1!B:D,3,FALSE),0) -> 0 | F27: =E27*D27 -> 0
B28: =IFERROR(VLOOKUP(C28,Sheet1!B:C,2,FALSE), ) -> 0 | E28: =IFERROR(VLOOKUP(C28,Sheet1!B:D,3,FALSE)*0,0) -> 0 | F28: =E28*D28 -> 0
E29: TOTAL | F29: =SUM(F12:F28) -> 2900
B30: Bonificação
B31: Código | C31: Descrição | D31: Quantidade | E31: Valor unitário | F31: Valor total
B32: =IFERROR(VLOOKUP(C32,Sheet1!B:C,2,FALSE), ) -> 003040854 | C32: Desumidificador KidCat Sonic | D32: 1 | E32: 18 | F32: =E32*D32 -> 18
B33: =IFERROR(VLOOKUP(C33,Sheet1!B:C,2,FALSE), ) -> 149283 | C33: Recep. 85 miniFit 3L | D33: 1 | E33: =IFERROR(VLOOKUP(C33,Sheet1!B:D,3,FALSE),0) -> 170 | F33: =E33*D33 -> 170
B34: =IFERROR(VLOOKUP(C34,Sheet1!B:C,2,FALSE), ) -> 149284 | C34: Recep. 85 miniFit 3R | D34: 1 | E34: =IFERROR(VLOOKUP(C34,Sheet1!B:D,3,FALSE),0) -> 170 | F34: =E34*D34 -> 170
B35: =IFERROR(VLOOKUP(C35,Sheet1!B:C,2,FALSE), ) -> 149315 | C35: Domo Power 8mm | D35: 1 | E35: =IFERROR(VLOOKUP(C35,Sheet1!B:D,3,FALSE),0) -> 50 | F35: =E35*D35 -> 50
B36: =IFERROR(VLOOKUP(C36,Sheet1!B:C,2,FALSE), ) -> 149316 | C36: Domo Power 10mm | D36: 1 | E36: =IFERROR(VLOOKUP(C36,Sheet1!B:D,3,FALSE),0) -> 50 | F36: =E36*D36 -> 50
B37: 130091 | C37: WAX PROTECTION SET PROWAX MINIFIT | D37: 2 | E37: =IFERROR(VLOOKUP(C37,Sheet1!B:D,3,FALSE),0) -> 71.3 | F37: =E37*D37 -> 142.6
B38: =IFERROR(VLOOKUP(C38,Sheet1!B:C,2,FALSE), ) -> 0 | E38: =IFERROR(VLOOKUP(C38,Sheet1!B:D,3,FALSE),0) -> 0 | F38: =E38*D38 -> 0
B39: =IFERROR(VLOOKUP(C39,Sheet1!B:C,2,FALSE), ) -> 0 | E39: =IFERROR(VLOOKUP(C39,Sheet1!B:D,3,FALSE),0) -> 0 | F39: =E39*D39 -> 0
E40: TOTAL | F40: =SUM(F32:F39) -> 600.6

Sheet Planilha1
A1: AASI | E1: Cond. Pagto | F1: Descricao | G1: Codigo
A2: RADIANT100 MNR RECARREGÁVEL | B2: 222291 | C2: 2800 | E2: 00 | F2: DEPOSITO EM CONTA | G2: 001
A3: RADIANT 100 MNR | B3: 230652 | C3: 2700 | E3: CARTÃO DE CRÉDITO | F3: PAGAMENTO CARTÃO | G3: CIELO
A4: RADIANT100 MNBTE | B4: 234745 | C4: 2500 | E4: 30 | F4: BOLETO 30 DIAS | G4: 009
A5: RADIANT100 CUSTOMIZADO | C5: 2500 | E5: 30,60 | F5: 2X BOLETO | G5: 102
A6: RADIANT 60 MNR RECARREGÁVEL | B6: 222305 | C6: 1800 | E6: 30,60,90 | F6: 3X BOLETO | G6: 011
A7: RADIANT 60 MNR | B7: 230666 | C7: 1650 | E7: 30,60,90,120 | F7: 4X BOLETO | G7: 086
A8: RADIANT 60 MNBTE | B8: 234759 | C8: 1575 | E8: 30,60,90,120,150 | F8: 5X BOLETO | G8: 105
A9: RADIANT 60 CUSTOMIZADO | C9: 1575 | E9: 30,60,90,120,150,180 | F9: 6X BOLETO | G9: 100
A10: RADIANT 20 MNR RECARREGÁVEL | B10: 240470 | C10: 1100 | E10: 30,60,90,120,150,180,210,240 | G10: 107
A11: RADIANT 20 MNR | B11: 240749 | C11: 935 | E11: 30,60,90,120,150,180,210,240,270,300 | G11: 871
A12: RADIANT 20 MNBTE | B12: 234772 | C12: 880 | E12: SEM | F12: BONI | G12: SEM
A13: RADIANT 20 CUSTOMIZADO | C13: 880 | E13: DEMO | F13: DEMO | G13: DEMO
A14: TREK 40 Super Power | B14: 248369 | C14: 1133
A15: TREK 40 Ultra Power | B15: 247787 | C15: 1133
A16: CARREGADOR SONIC PLUS | B16: 225683 | C16: 600
A17: CARREGADOR SONIC MESA | B17: 200309 | C17: 400
A18: CAPTIVATE 100 MINIRITE Recarregável | B18: 197014 | C18: 2200
A19: CAPTIVATE 100 MINIRITE | B19: 196447 | C19: 2178
A20: CAPTIVATE 100 BTE 105 | B20: 196429 | C20: 1925
A21: CAPTIVATE 80 MINIRITE Recarregável | B21: 197020 | C21: 1600
A22: CAPTIVATE 80 MINIRITE | B22: 196454 | C22: 1628
A23: CAPTIVATE 80 BTE 105 | B23: 196435 | C23: 1573
A24: CAPTIVATE 60 MINIRITE Recarregável | B24: 197026 | C24: 1400
A25: CAPTIVATE 60 MINIRITE | B25: 196460 | C25: 1265
... A31: CAPTIVATE 20 BTE 105 | B31: 215355 | C31: 770
A33: RECEPTORES
A34: Recep. 60 miniFit 1L | B34: 149272 | C34: =VLOOKUP(B34,[1]Sheet3!$C:$F,4,FALSE) -> 170
A35: Recep. 60 miniFit 1R | B35: 149271 | C35: 170
A36: Recep. 60 miniFit 2L | B36: 149274 | C36: 170
A37: Recep. 60 miniFit 2R | B37: 149273 | C37: 170
A38: Recep. 60 miniFit 3L | B38: 149276 | C38: 170
A39: Recep. 60 miniFit 3R | B39: 149275 | C39: 170
A40: Recep. 60 miniFit 4L | B40: 149278 | C40: 170
A41: Recep. 60 miniFit 4R | B41: 149277 | C41: 170
A42: Recep. 85 miniFit 1L | B42: 149279 | C42: 170
A43: Recep. 85 miniFit 1R | B43: 149280 | C43: 170
A44: Recep. 85 miniFit 2L | B44: 149281 | C44: 170
A45: Recep. 85 miniFit 2R | B45: 149282 | C45: 170
A46: Recep. 85 miniFit 3L | B46: 149283 | C46: 170
...

Sheet ENDEREÇAMENTO
A1: Pedido de Faturamento, Para faturamento segue o pedido em referência onde solicito o encaminhamento para o seguinte endereço: Destinatário: Fga Brendda Maia de Sousa Empresa: ASSOCIAÇÃO DOS SURDOS E MUDOS DE UBERLÂNDIA - ASUL Endereço: RUA MATHEUS VAZ Complemento – N° 865 Bairro: LUIZOTE DE FREITAS II Cidade: Uberlândia Estado: MG CEP: 38.414-308 OBSERVAÇÃO: Favor informar no campo ‘INFORMAÇÕES COMPLEMENTARES” das NF´s da TELEX e ATOMED o número do nosso pedido e nome do paciente indicados acima em referência. At.te

Sheet Sheet2

Sheet Sheet1
B3: AASI | F3: Cond. Pagto | G3: Descricao | H3: Codigo
B4: RADIANT100 MNR RECARREGÁVEL | C4: 222291 | D4: 2800 | F4: 00 | G4: DEPOSITO EM CONTA | H4: 001
B5: RADIANT 100 MNR | C5: 230652 | D5: 2700 | F5: CARTÃO DE CRÉDITO | G5: PAGAMENTO CARTÃO | H5: CIELO
B6: RADIANT100 MNBTE | C6: 234745 | D6: 2500 | F6: 30 | G6: BOLETO 30 DIAS | H6: 009
B7: RADIANT100 CUSTOMIZADO | D7: 2500 | F7: 30,60 | G7: 2X BOLETO | H7: 102
B8: RADIANT 60 MNR RECARREGÁVEL | C8: 222305 | D8: 1800 | F8: 30,60,90 | G8: 3X BOLETO | H8: 011
B9: RADIANT 60 MNR | C9: 230666 | D9: 1650 | F9: 30,60,90,120 | G9: 4X BOLETO | H9: 086
B10: RADIANT 60 MNBTE | C10: 234759 | D10: 1575 | F10: 30,60,90,120,150 | G10: 5X BOLETO | H10: 105
B11: RADIANT 60 CUSTOMIZADO | D11: 1575 | F11: 30,60,90,120,150,180 | G11: 6X BOLETO | H11: 100
B12: RADIANT 20 MNR RECARREGÁVEL | C12: 240470 | D12: 1100 | F12: 30,60,90,120,150,180,210,240 | H12: 107
B13: RADIANT 20 MNR | C13: 240749 | D13: 935 | F13: 30,60,90,120,150,180,210,240,270,300 | H13: 871
B14: RADIANT 20 MNBTE | C14: 234772 | D14: 880 | F14: SEM | G14: BONI | H14: SEM
B15: RADIANT 20 CUSTOMIZADO | D15: 880 | F15: DEMO | G15: DEMO | H15: DEMO
B16: TREK 40 Super Power | C16: 248369 | D16: 1133
B17: TREK 40 Ultra Power | C17: 247787 | D17: 1133
B18: CARREGADOR SONIC PLUS | C18: 225683 | D18: 600
B19: CARREGADOR SONIC MESA | C19: 200309 | D19: 400
B20: CAPTIVATE 100 MINIRITE Recarregável | C20: 197014 | D20: 2200
B21: CAPTIVATE 100 MINIRITE | C21: 196447 | D21: 2178
B22: CAPTIVATE 100 BTE 105 | C22: 196429 | D22: 1925
B23: CAPTIVATE 80 MINIRITE Recarregável | C23: 197020 | D23: 1600
B24: CAPTIVATE 80 MINIRITE | C24: 196454 | D24: 1628
B25: CAPTIVATE 80 BTE 105 | C25: 196435 | D25: 1573
B26: CAPTIVATE 60 MINIRITE Recarregável | C26: 197026 | D26: 1400
B27: CAPTIVATE 60 MINIRITE | C27: 196460 | D27: 1265
... B33: CAPTIVATE 20 BTE 105 | C33: 215355 | D33: 770
B35: RECEPTORES
B36: Recep. 60 miniFit 1L | C36: 149272 | D36: =VLOOKUP(C36,[1]Sheet3!$C:$F,4,FALSE) -> 170
B37: Recep. 60 miniFit 1R | C37: 149271 | D37: 170
B38: Recep. 60 miniFit 2L | C38: 149274 | D38: 170
B39: Recep. 60 miniFit 2R | C39: 149273 | D39: 170
B40: Recep. 60 miniFit 3L | C40: 149276 | D40: 170
B41: Recep. 60 miniFit 3R | C41: 149275 | D41: 170
B42: Recep. 60 miniFit 4L | C42: 149278 | D42: 170
B43: Recep. 60 miniFit 4R | C43: 149277 | D43: 170
B44: Recep. 85 miniFit 1L | C44: 149279 | D44: 170
B45: Recep. 85 miniFit 1R | C45: 149280 | D45: 170
B46: Recep. 85 miniFit 2L | C46: 149281 | D46: 170
B47: Recep. 85 miniFit 2R | C47: 149282 | D47: 170
B48: Recep. 85 miniFit 3L | C48: 149283 | D48: 170
...
